Workbook

Sheet Исходные данные
A1: Субъект | B1: X1 | C1: X2 | D1: X3 | E1: X4 | F1: X5 | G1: X6 | H1: X7 | I1: X8 | J1: X9 | L1: Обозначение | M1: Название
A2: Белгородская область | B2: 141 | C2: 313.6 | D2: 773.9 | E2: 698 | F2: 90 | G2: 78.3 | H2: 112.4 | I2: 105.3 | J2: 111.4 | L2: X1 | M2: Численность населения на одну больничную койку
A3: Брянская область | B3: 132.6 | C3: 324.1 | D3: 822.6 | E3: 332 | F3: 120 | G3: 44 | H3: 110.9 | I3: 107.6 | J3: 107 | L3: X2 | M3: Мощность амбулаторно-поликлинических организаций
A4: Владимирская область | B4: 122.5 | C4: 400.9 | D4: 1021.1 | E4: 400 | F4: 72 | G4: 143 | H4: 110.8 | I4: 115.9 | J4: 102 | L4: X3 | M4: Заболеваемость на 1 000 человек населения
A5: Воронежская область | B5: 129.3 | C5: 279 | D5: 591.8 | E5: 440 | F5: 105 | G5: 113 | H5: 111.9 | I5: 112.8 | J5: 111.7 | L5: X4 | M5: Плотность автомобильных дорог общего пользования с твердым покрытием
A6: Ивановская область | B6: 109.3 | C6: 293 | D6: 805.7 | E6: 340 | F6: 118 | G6: 117.6 | H6: 111.2 | I6: 107.2 | J6: 101.6 | L6: X5 | M6: Число автобусов общего пользования на 100 000 человек населения
A7: Калужская область | B7: 151.1 | C7: 268.5 | D7: 1072.3 | E7: 367 | F7: 108 | G7: 104.7 | H7: 110.8 | I7: 107.4 | J7: 107.3 | L7: X6 | M7: Число дорожно-транспортных происшествий и пострадавших в них на 100 000 человек населения
A8: Костромская область | B8: 101.5 | C8: 319.1 | D8: 777.2 | E8: 140 | F8: 103 | G8: 173.4 | H8: 110.5 | I8: 109.3 | J8: 97.4 | L8: X7 | M8: Индексы потребительских цен на продовольственные товары
A9: Курская область | B9: 124.6 | C9: 293.4 | D9: 578.1 | E9: 378 | F9: 95 | G9: 112.3 | H9: 112.3 | I9: 112.2 | J9: 102.5 | L9: X8 | M9: Индексы цен на первичном рынке жилья
A10: Липецкая область | B10: 123.2 | C10: 371.1 | D10: 642.5 | E10: 572 | F10: 115 | G10: 100.7 | H10: 112.7 | I10: 105.9 | J10: 110.8 | L10: X9 | M10: Индексы тарифов на грузовые перевозки
A11: Московская область | B11: 162.9 | C11: 251.5 | D11: 687.6 | E11: 862 | F11: 111 | G11: 45.1 | H11: 111.2 | I11: 100.8 | J11: 119.9
A12: Орловская область | B12: 117.4 | C12: 314.4 | D12: 1121.1 | E12: 412 | F12: 101 | G12: 95.6 | H12: 111.8 | I12: 106.8 | J12: 119.2
A13: Рязанская область | B13: 142.4 | C13: 283.7 | D13: 812.9 | E13: 287 | F13: 97 | G13: 133.4 | H13: 111.1 | I13: 109.4 | J13: 109.6
A14: Смоленская область | B14: 108.4 | C14: 344.2 | D14: 653 | E14: 338 | F14: 111 | G14: 97.8 | H14: 111.1 | I14: 111.1 | J14: 118.7
A15: Тамбовская область | B15: 127.9 | C15: 325.1 | D15: 683.7 | E15: 297 | F15: 84 | G15: 110.7 | H15: 113.6 | I15: 109.9 | J15: 129.3
A16: Тверская область | B16: 108.1 | C16: 265.5 | D16: 806.4 | E16: 255 | F16: 83 | G16: 119.7 | H16: 112.2 | I16: 109.2 | J16: 110.9
A17: Тульская область | B17: 126.4 | C17: 279 | D17: 741.1 | E17: 430 | F17: 130 | G17: 115.5 | H17: 111.7 | I17: 108.7 | J17: 118.8
A18: Ярославская область | B18: 110.1 | C18: 322.5 | D18: 888.9 | E18: 289 | F18: 116 | G18: 117.8 | H18: 112.2 | I18: 106.7 | J18: 113.3
A19: г. Москва | B19: 175.6 | C19: 535.4 | D19: 674 | E19: 2559 | F19: 71 | G19: 67.7 | H19: 111.2 | I19: 107.9 | J19: 105.2
A20: Республика Карелия | B20: 121.3 | C20: 361 | D20: 1486.9 | E20: 49 | F20: 78 | G20: 140.8 | H20: 110.5 | I20: 107.3 | J20: 106.6
A21: Республика Коми | B21: 96.2 | C21: 474.3 | D21: 1189.8 | E21: 17 | F21: 98 | G21: 119.3 | H21: 108.1 | I21: 114 | J21: 87.2
A22: Ненецкий автономный округ | B22: 179.1 | C22: 284.9 | D22: 1350.3 | E22: 1.9 | F22: 93 | G22: 40.4 | H22: 107 | I22: 96.7 | J22: 105.5
... A86: Чукотский автономный округ | B86: 73.6 | C86: 483.7 | D86: 1130.9 | E86: 1.3 | F86: 86 | G86: 29.2 | H86: 105 | I86: 105.3 | J86: 109.5

Sheet Стандартизированные данные
A1: Субъект | B1: X1 | C1: X2 | D1: X3 | E1: X4 | F1: X5 | G1: X6 | H1: X7 | I1: X8 | J1: X9 | K1: кластер по методу полных связей | L1: кластер по взвешенному методу средней связи | M1: кластер по методу Уорда | N1: кластер по методу k-средних
A2: Белгородская область | B2: 0.61790357 | C2: 0.009332148 | D2: -0.32232839 | E2: 0.90139708 | F2: -0.27984288 | G2: -0.62225576 | H2: 0.97882517 | I2: -0.84276281 | J2: 0.25865706 | K2: 5 | L2: 5 | M2: 4 | N2: =VLOOKUP(A:A,'k-средних'!$A$2:$B$86,2,0) -> 3
A3: Брянская область | B3: 0.26165103 | C3: 0.15571074 | D3: -0.081861548 | E3: 0.041336011 | F3: 0.94207381 | G3: -1.5793577 | H3: 0.13443945 | I3: -0.49048543 | J3: -0.32480337 | K3: 5 | L3: 5 | M3: 3 | N3: =VLOOKUP(A:A,'k-средних'!$A$2:$B$86,2,0) -> 1
A4: Владимирская область | B4: -0.16670025 | C4: 1.2263656 | D4: 0.89827539 | E4: 0.20112878 | F4: -1.0129929 | G4: 1.1831231 | H4: 0.07814707 | I4: 0.7807764 | J4: -0.98782658 | K4: 6 | L4: 5 | M4: 2 | N4: =VLOOKUP(A:A,'k-средних'!$A$2:$B$86,2,0) -> 2
A5: Воронежская область | B5: 0.12169467 | C5: -0.47302018 | D5: -1.2214868 | E5: 0.29512452 | F5: 0.33111546 | G5: 0.34600769 | H5: 0.69736326 | I5: 0.30596777 | J5: 0.29843845 | K5: 5 | L5: 5 | M5: 3 | N5: =VLOOKUP(A:A,'k-средних'!$A$2:$B$86,2,0) -> 3
A6: Ивановская область | B6: -0.72652567 | C6: -0.27784872 | D6: -0.16530898 | E6: 0.06013516 | F6: 0.86061269 | G6: 0.47436538 | H6: 0.3033166 | I6: -0.55175106 | J6: -1.0408684 | K6: 6 | L6: 5 | M6: 3 | N6: =VLOOKUP(A:A,'k-средних'!$A$2:$B$86,2,0) -> 2
A7: Калужская область | B7: 1.0462548 | C7: -0.61939877 | D7: 1.1510865 | E7: 0.12358229 | F7: 0.45330713 | G7: 0.11440577 | H7: 0.07814707 | I7: -0.52111825 | J7: -0.28502198 | K7: 5 | L7: 5 | M7: 3 | N7: =VLOOKUP(A:A,'k-средних'!$A$2:$B$86,2,0) -> 1
A8: Костромская область | B8: -1.0573316 | C8: 0.086006651 | D8: -0.30603393 | E8: -0.40984356 | F8: 0.24965435 | G8: 2.0314 | H8: -0.090730073 | I8: -0.2301065 | J8: -1.5978079 | K8: 6 | L8: 5 | M8: 3 | N8: =VLOOKUP(A:A,'k-средних'!$A$2:$B$86,2,0) -> 2
A9: Курская область | B9: -0.077637109 | C9: -0.27227239 | D9: -1.2891335 | E9: 0.14943112 | F9: -0.076190099 | G9: 0.32647499 | H9: 0.92253279 | I9: 0.21406932 | J9: -0.92152426 | K9: 5 | L9: 5 | M9: 3 | N9: =VLOOKUP(A:A,'k-средних'!$A$2:$B$86,2,0) -> 3
A10: Липецкая область | B10: -0.13701253 | C10: 0.81092922 | D10: -0.97114448 | E10: 0.60531048 | F10: 0.73842102 | G10: 0.0027903846 | H10: 1.1477023 | I10: -0.75086436 | J10: 0.17909427 | K10: 5 | L10: 5 | M10: 3 | N10: =VLOOKUP(A:A,'k-средних'!$A$2:$B$86,2,0) -> 3
A11: Московская область | B11: 1.5467049 | C11: -0.85639269 | D11: -0.74845342 | E11: 1.2867796 | F11: 0.5754988 | G11: -1.5486634 | H11: 0.3033166 | I11: -1.5320011 | J11: 1.3857965 | K11: 3 | L11: 5 | M11: 4 | N11: =VLOOKUP(A:A,'k-средних'!$A$2:$B$86,2,0) -> 4
A12: Орловская область | B12: -0.38299643 | C12: 0.020484803 | D12: 1.3920471 | E12: 0.2293275 | F12: 0.16819324 | G12: -0.13951923 | H12: 0.64107088 | I12: -0.61301669 | J12: 1.2929733 | K12: 5 | L12: 5 | M12: 3 | N12: =VLOOKUP(A:A,'k-средних'!$A$2:$B$86,2,0) -> 1
A13: Рязанская область | B13: 0.677279 | C13: -0.40749833 | D13: -0.12975741 | E13: -0.064409202 | F13: 0.0052710132 | G13: 0.91524614 | H13: 0.24702421 | I13: -0.21479009 | J13: 0.019968699 | K13: 5 | L13: 5 | M13: 3 | N13: =VLOOKUP(A:A,'k-средних'!$A$2:$B$86,2,0) -> 3
... A33: Республика Крым | B33: -0.18366465 | C33: -1.4419071 | D33: -1.1503836 | E33: 0.47606633 | F33: 0.5754988 | G33: -0.90129422 | H33: 0.86624041 | I33: 1.6844445 | J33: 0.56364773 | K33: 3 | L33: 5 | M33: 4 | N33: =VLOOKUP(A:A,'k-средних'!$A$2:$B$86,2,0) -> 3
A34: Краснодарский край | B34: 0.42281289 | C34: -0.85499861 | D34: -0.72919632 | E34: 0.41026931 | F34: -0.15765121 | G34: 0.13393846 | H34: 0.69736326 | I34: -1.3635207 | J34: 0.36474077 | K34: 5 | L34: 5 | M34: 4 | N34: 3
A35: Астраханская область | B35: -0.43813076 | C35: -0.36567587 | D35: -0.7854863 | E35: -0.53908771 | F35: 0.5754988 | G35: -0.025113461 | H35: -0.3158996 | I35: 1.0717881 | J35: -0.099375479 | K35: 5 | L35: 5 | M35: 3 | N35: =VLOOKUP(A:A,'k-средних'!$A$2:$B$86,2,0) -> 3
A36: Волгоградская область | B36: -0.51447059 | C36: -0.39913384 | D36: -0.97558843 | E36: -0.37459516 | F36: -0.68714844 | G36: 0.0027903846 | H36: 0.13443945 | I36: 0.61229592 | J36: 1.6377453 | K36: 5 | L36: 5 | M36: 3 | N36: =VLOOKUP(A:A,'k-средних'!$A$2:$B$86,2,0) -> 3
A37: Ростовская область | B37: -0.46357737 | C37: 0.92942618 | D37: -0.27295122 | E37: -0.090258032 | F37: -0.56495677 | G37: -0.8315346 | H37: 1.0351176 | I37: 0.48976466 | J37: 0.47082448 | K37: 5 | L37: 5 | M37: 3 | N37: =VLOOKUP(A:A,'k-средних'!$A$2:$B$86,2,0) -> 3
A38: г. Севастополь | B38: 1.0250493 | C38: -1.4990644 | D38: -1.5928031 | E38: 2.0904432 | F38: 0.94207381 | G38: -0.62783653 | H38: 1.3165795 | I38: 1.8222921 | J38: 0.56364773 | K38: 3 | L38: 5 | M38: 4 | N38: =VLOOKUP(A:A,'k-средних'!$A$2:$B$86,2,0) -> 4
A39: Республика Дагестан | B39: 0.63486798 | C39: -2.8722351 | D39: -0.23986851 | E39: 0.34212239 | F39: -0.44276511 | G39: -1.3896115 | H39: 2.1046728 | I39: 0.1681201 | J39: 0.32495938 | K39: 3 | L39: 5 | M39: 4 | N39: =VLOOKUP(A:A,'k-средних'!$A$2:$B$86,2,0) -> 3
A40: Республика Ингушетия | B40: 4.1295358 | C40: -2.0748202 | D40: -1.6377364 | E40: 1.7309095 | F40: -0.15765121 | G40: -1.7412 | H40: -0.3158996 | I40: 0.81140922 | J40: 0.059750092 | K40: 3 | L40: 5 | M40: 4 | N40: =VLOOKUP(A:A,'k-средних'!$A$2:$B$86,2,0) -> 4
A41: Кабардино-Балкарская Республика | B41: 0.91053959 | C41: -1.4182077 | D41: -1.5641644 | E41: 0.8919975 | F41: 1.8788766 | G41: -0.75340383 | H41: 1.0351176 | I41: -0.56706747 | J41: -0.19219873 | K41: 3 | L41: 5 | M41: 4 | N41: =VLOOKUP(A:A,'k-средних'!$A$2:$B$86,2,0) -> 3
A42: Карачаево-Черкесская Республика | B42: 1.3134443 | C42: -0.94700801 | D42: 0.41882301 | E42: 0.11183282 | F42: -1.6646818 | G42: -0.73387114 | H42: 0.64107088 | I42: -1.5473176 | J42: 0.033229163 | K42: 5 | L42: 5 | M42: 4 | N42: =VLOOKUP(A:A,'k-средних'!$A$2:$B$86,2,0) -> 1
A43: Республика Северная Осетия – Алания | B43: -0.71804347 | C43: -0.29736586 | D43: -0.91682959 | E43: 0.93664548 | F43: 4.32271 | G43: 0.97105383 | H43: 1.2602871 | I43: 3.1854524 | J43: -1.2530359 | K43: 1 | L43: 2 | M43: 1 | N43: =VLOOKUP(A:A,'k-средних'!$A$2:$B$86,2,0) -> 3
A44: Чеченская Республика | B44: 2.1955934 | C44: -1.5617981 | D44: -2.0480607 | E44: 0.79800176 | F44: -0.15765121 | G44: -2.5169269 | H44: -0.37219198 | I44: 0.45913184 | J44: -1.2132545 | K44: 3 | L44: 5 | M44: 4 | N44: =VLOOKUP(A:A,'k-средних'!$A$2:$B$86,2,0) -> 4
A45: Ставропольский край | B45: -0.026743889 | C45: -1.1589085 | D45: 0.1586053 | E45: -0.07615867 | F45: -1.094454 | G45: -0.2706673 | H45: 1.7106261 | I45: 1.9754562 | J45: 0.3912617 | K45: 5 | L45: 5 | M45: 3 | N45: =VLOOKUP(A:A,'k-средних'!$A$2:$B$86,2,0) -> 3
A46: Республика Башкортостан | B46: 0.35495527 | C46: -0.52738937 | D46: 1.569805 | E46: 0.03428633 | F46: 0.046001569 | G46: -0.77293653 | H46: -0.20331484 | I46: 0.26001854 | J46: -0.28502198 | K46: 5 | L46: 5 | M46: 3 | N46: =VLOOKUP(A:A,'k-средних'!$A$2:$B$86,2,0) -> 1
... A53: Кировская область | B53: -1.0827782 | C53: 0.228203 | D53: 0.14477969 | E53: -0.46389112 | F53: -0.15765121 | G53: 1.1440577 | H53: 0.69736326 | I53: -0.58238388 | J53: -0.11263594 | K53: 6 | L53: 5 | M53: 3 | N53: =VLOOKUP(A:A,'k-средних'!$A$2:$B$86,2,0) -> 2
A54: Нижегородская область | B54: -0.72228457 | C54: 0.13898176 | D54: 0.66373381 | E54: 0.0084375004 | F54: 0.53476824 | G54: 1.4175154 | H54: -0.20331484 | I54: 0.10685447 | J54: 0.13931288 | K54: 6 | L54: 5 | M54: 3 | N54: 2
A55: Оренбургская область | B55: 0.30406205 | C55: 0.10134155 | D55: 0.74668746 | E55: -0.3581459 | F55: 0.29038491 | G55: -0.90687498 | H55: -0.034437692 | I55: -0.030993201 | J55: -0.81544055 | K55: 5 | L55: 5 | M55: 3 | N55: =VLOOKUP(A:A,'k-средних'!$A$2:$B$86,2,0) -> 1
A56: Пензенская область | B56: -0.20487016 | C56: -0.45489711 | D56: -0.25665675 | E56: -0.083208351 | F56: 0.046001569 | G56: 0.8315346 | H56: 0.52848612 | I56: -0.39858698 | J56: -0.25850105 | K56: 5 | L56: 5 | M56: 3 | N56: =VLOOKUP(A:A,'k-средних'!$A$2:$B$86,2,0) -> 3
A57: Самарская область | B57: 0.55004595 | C57: -0.42283323 | D57: 0.36845829 | E57: 0.093033671 | F57: -0.60568733 | G57: -0.092082691 | H57: 0.3033166 | I57: 0.3672334 | J57: 0.28517798 | K57: 5 | L57: 5 | M57: 3 | N57: =VLOOKUP(A:A,'k-средних'!$A$2:$B$86,2,0) -> 1
A58: Саратовская область | B58: -0.63322144 | C58: -0.068736437 | D58: -0.69611361 | E58: -0.30644824 | F58: -0.68714844 | G58: 0.19253654 | H58: 0.24702421 | I58: 0.41318262 | J58: 0.32495938 | K58: 5 | L58: 5 | M58: 3 | N58: =VLOOKUP(A:A,'k-средних'!$A$2:$B$86,2,0) -> 3
A59: Ульяновская область | B59: -0.24304008 | C59: -0.0018205069 | D59: -0.70006379 | E59: -0.11845676 | F59: 0.33111546 | G59: -0.61667499 | H59: -0.54106912 | I59: 0.68887796 | J59: -0.76239869 | K59: 5 | L59: 5 | M59: 3 | N59: =VLOOKUP(A:A,'k-средних'!$A$2:$B$86,2,0) -> 3
A60: Курганская область | B60: -0.34058542 | C60: -0.14122869 | D60: 1.7910147 | E60: -0.41219346 | F60: -0.64641789 | G60: 0.19253654 | H60: 0.13443945 | I60: 1.4087491 | J60: 0.85537795 | K60: 5 | L60: 5 | M60: 3 | N60: =VLOOKUP(A:A,'k-средних'!$A$2:$B$86,2,0) -> 1
A61: Свердловская область | B61: -0.5568816 | C61: 0.15431666 | D61: 0.69286634 | E61: -0.42864271 | F61: -0.93153178 | G61: -1.0017481 | H61: 0.35960898 | I61: 0.35191699 | J61: 0.11279195 | K61: 5 | L61: 5 | M61: 3 | N61: 1
A62: Ханты-Мансийский автономный округ – Югра | B62: 0.60518027 | C62: -0.67795021 | D62: 0.007017368 | E62: -0.71062995 | F62: -1.1351846 | G62: -0.89013268 | H62: -0.54106912 | I62: -0.30668854 | J62: 0.27191752 | K62: 5 | L62: 5 | M62: 3 | N62: =VLOOKUP(A:A,'k-средних'!$A$2:$B$86,2,0) -> 1
A63: Ямало-Ненецкий автономный округ | B63: -0.014020583 | C63: -0.33500607 | D63: 3.0318632 | E63: -0.73013406 | F63: -0.727879 | G63: -1.1524288 | H63: -1.3854548 | I63: -0.38327058 | J63: 1.0410244 | K63: 6 | L63: 6 | M63: 2 | N63: =VLOOKUP(A:A,'k-средних'!$A$2:$B$86,2,0) -> 1
A64: Тюменская область без автономных округов | B64: 0.60942137 | C64: -0.18444523 | D64: -0.44182116 | E64: -0.52028856 | F64: 2.6934877 | G64: 2.0844173 | H64: -1.7232091 | I64: -0.32200495 | J64: -0.29828244 | K64: 6 | L64: 6 | M64: 1 | N64: =VLOOKUP(A:A,'k-средних'!$A$2:$B$86,2,0) -> 2
A65: Челябинская область | B65: 0.4440184 | C65: 0.59902878 | D65: 0.61583794 | E65: -0.14900537 | F65: -0.035459543 | G65: 0.09766346 | H65: -0.48477674 | I65: 0.3672334 | J65: 0.52386634 | K65: 6 | L65: 5 | M65: 3 | N65: =VLOOKUP(A:A,'k-средних'!$A$2:$B$86,2,0) -> 1
...

Sheet полных_связей
A1: Субъект | B1: кластер | C1: X1 | D1: X2 | E1: X3 | F1: X4 | G1: X5 | H1: X6 | I1: X7 | J1: X8 | K1: X9
A2: Республика Северная Осетия – Алания | B2: 1 | C2: -0.71804347 | D2: -0.29736586 | E2: -0.91682959 | F2: 0.93664548 | G2: 4.32271 | H2: 0.97105383 | I2: 1.2602871 | J2: 3.1854524 | K2: -1.2530359
A3: срзнач
A6: Q1(S) | B6: 0
A7: г. Москва | B7: 2 | C7: 2.0853248 | D7: 3.1014057 | E7: -0.81560638 | F7: 5.2745491 | G7: -1.0537234 | H7: -0.91803652 | I7: 0.3033166 | J7: -0.44453621 | K7: -0.56349173
A8: г. Санкт-Петербург | B8: 2 | C8: -0.42964855 | D8: 1.1873313 | E8: 0.86766154 | F8: 5.2651495 | G8: 0.33111546 | H8: -0.82037306 | I8: 0.19073183 | J8: -0.79681358 | K8: 0.92168027
A9: срзнач | C9: =AVERAGE(C7:C8) -> 0.82783811 | D9: =AVERAGE(D7:D8) -> 2.1443685 | E9: =AVERAGE(E7:E8) -> 0.026027581 | F9: =AVERAGE(F7:F8) -> 5.2698493 | G9: =AVERAGE(G7:G8) -> -0.36130399 | H9: =AVERAGE(H7:H8) -> -0.86920479 | I9: =AVERAGE(I7:I8) -> 0.24702421 | J9: =AVERAGE(J7:J8) -> -0.6206749 | K9: =AVERAGE(K7:K8) -> 0.17909427
C10: 2.067128 | D10: 2.067128
C11: =C10*C10 -> 4.2730182 | D11: =D10*D10 -> 4.2730182
A12: Q2(S) | B12: =SUM(C11:D11) -> 8.5460363
A13: Московская область | B13: 3 | C13: 1.5467049 | D13: -0.85639269 | E13: -0.74845342 | F13: 1.2867796 | G13: 0.5754988 | H13: -1.5486634 | I13: 0.3033166 | J13: -1.5320012 | K13: 1.3857965
A14: Республика Крым | B14: 3 | C14: -0.18366465 | D14: -1.4419071 | E14: -1.1503836 | F14: 0.47606633 | G14: 0.5754988 | H14: -0.90129422 | I14: 0.86624041 | J14: 1.6844444 | K14: 0.56364773
A15: г. Севастополь | B15: 3 | C15: 1.0250493 | D15: -1.4990644 | E15: -1.5928031 | F15: 2.0904432 | G15: 0.94207381 | H15: -0.62783653 | I15: 1.3165795 | J15: 1.8222921 | K15: 0.56364773
A16: Республика Дагестан | B16: 3 | C16: 0.63486798 | D16: -2.8722351 | E16: -0.23986851 | F16: 0.3421224 | G16: -0.44276511 | H16: -1.3896115 | I16: 2.1046728 | J16: 0.1681201 | K16: 0.32495938
A17: Республика Ингушетия | B17: 3 | C17: 4.1295358 | D17: -2.0748202 | E17: -1.6377364 | F17: 1.7309095 | G17: -0.15765121 | H17: -1.7412 | I17: -0.3158996 | J17: 0.81140922 | K17: 0.059750092
A18: Кабардино-Балкарская Республика | B18: 3 | C18: 0.91053959 | D18: -1.4182077 | E18: -1.5641644 | F18: 0.8919975 | G18: 1.8788766 | H18: -0.75340383 | I18: 1.0351176 | J18: -0.56706747 | K18: -0.19219873
A19: Чеченская Республика | B19: 3 | C19: 2.1955934 | D19: -1.5617981 | E19: -2.0480607 | F19: 0.79800176 | G19: -0.15765121 | H19: -2.5169269 | I19: -0.37219198 | J19: 0.45913184 | K19: -1.2132545
A20: срзнач | C20: =AVERAGE(C13:C19) -> 1.465518 | D20: =AVERAGE(D13:D19) -> -1.6749179 | E20: =AVERAGE(E13:E19) -> -1.2830672 | F20: =AVERAGE(F13:F19) -> 1.0880458 | G20: =AVERAGE(G13:G19) -> 0.45912578 | H20: =AVERAGE(H13:H19) -> -1.3541338 | I20: =AVERAGE(I13:I19) -> 0.70540503 | J20: =AVERAGE(J13:J19) -> 0.40661844 | K20: =AVERAGE(K13:K19) -> 0.21319261
C21: 2.272961 | D21: 2.141706 | E21: 2.571031 | F21: 3.091387 | G21: 2.022137 | H21: 2.479188
C22: =C21*C21 -> 5.1663517 | D22: =D21*D21 -> 4.5869046 | E22: =E21*E21 -> 6.6102004 | F22: =F21*F21 -> 9.5566736 | G22: =G21*G21 -> 4.089038 | H22: =H21*H21 -> 6.1463731
A23: Q3(S) | B23: =SUM(C22:H22) -> 36.155541
A24: Новгородская область | B24: 4 | C24: -0.24728118 | D24: 3.9434312 | E24: -0.4324395 | F24: -0.26650005 | G24: -0.27984288 | H24: 0.61388461 | I24: -0.48477674 | J24: 0.15280369 | K24: 0.15257334
A25: Магаданская область | B25: 4 | C25: -0.76045449 | D25: 1.4340838 | E25: -0.45811563 | F25: -0.72613925 | G25: 0.046001569 | H25: 0.73387114 | I25: -3.1305187 | J25: -0.73554795 | K25: 2.5261964
A26: Чукотский автономный округ | B26: 4 | C26: -2.240599 | D26: 2.3806654 | E26: 1.4404368 | F26: -0.73577381 | G26: -0.44276511 | H26: -1.9923346 | I26: -3.186811 | J26: -0.84276281 | K26: 0.0067082348
A27: срзнач | C27: =AVERAGE(C24:C26) -> -1.0827782 | D27: =AVERAGE(D24:D26) -> 2.5860601 | E27: =AVERAGE(E24:E26) -> 0.18329389 | F27: =AVERAGE(F24:F26) -> -0.5761377 | G27: =AVERAGE(G24:G26) -> -0.22553547 | H27: =AVERAGE(H24:H26) -> -0.21485961 | I27: =AVERAGE(I24:I26) -> -2.2673688 | J27: =AVERAGE(J24:J26) -> -0.47516902 | K27: =AVERAGE(K24:K26) -> 0.89515934
C28: 2.797981 | D28: 2.512325 | E28: 2.822247
C29: =C28*C28 -> 7.8286977 | D29: =D28*D28 -> 6.3117769 | E29: =E28*E28 -> 7.9650781
A30: Q4(S) | B30: =SUM(C29:E29) -> 22.105553
A31: Белгородская область | B31: 5 | C31: 0.61790357 | D31: 0.009332148 | E31: -0.32232839 | F31: 0.90139708 | G31: -0.27984288 | H31: -0.62225576 | I31: 0.97882517 | J31: -0.84276281 | K31: 0.25865706
A32: Брянская область | B32: 5 | C32: 0.26165103 | D32: 0.15571074 | E32: -0.081861548 | F32: 0.041336011 | G32: 0.94207381 | H32: -1.5793577 | I32: 0.13443945 | J32: -0.49048543 | K32: -0.32480337
A33: Воронежская область | B33: 5 | C33: 0.12169467 | D33: -0.47302018 | E33: -1.2214868 | F33: 0.29512452 | G33: 0.33111546 | H33: 0.34600769 | I33: 0.69736326 | J33: 0.30596777 | K33: 0.29843845
A34: Калужская область | B34: 5 | C34: 1.0462548 | D34: -0.61939877 | E34: 1.1510865 | F34: 0.12358229 | G34: 0.45330713 | H34: 0.11440577 | I34: 0.07814707 | J34: -0.52111825 | K34: -0.28502198
A35: Курская область | B35: 5 | C35: -0.077637109 | D35: -0.27227239 | E35: -1.2891335 | F35: 0.14943112 | G35: -0.076190099 | H35: 0.326475 | I35: 0.92253279 | J35: 0.21406932 | K35: -0.92152426
A36: Липецкая область | B36: 5 | C36: -0.13701253 | D36: 0.81092922 | E36: -0.97114448 | F36: 0.60531048 | G36: 0.73842103 | H36: 0.0027903846 | I36: 1.1477023 | J36: -0.75086436 | K36: 0.17909427
A37: Орловская область | B37: 5 | C37: -0.38299643 | D37: 0.020484803 | E37: 1.3920472 | F37: 0.2293275 | G37: 0.16819324 | H37: -0.13951923 | I37: 0.64107088 | J37: -0.61301669 | K37: 1.2929733
A38: Рязанская область | B38: 5 | C38: 0.677279 | D38: -0.40749833 | E38: -0.12975741 | F38: -0.064409202 | G38: 0.0052710132 | H38: 0.91524614 | I38: 0.24702421 | J38: -0.21479009 | K38: 0.019968699
A39: Смоленская область | B39: 5 | C39: -0.76469559 | D39: 0.4359212 | E39: -0.91929845 | F39: 0.055435373 | G39: 0.5754988 | H39: -0.078130768 | I39: 0.24702421 | J39: 0.045588837 | K39: 1.2266709
A40: Тамбовская область | B40: 5 | C40: 0.062319248 | D40: 0.16965156 | E40: -0.76771052 | F40: -0.040910266 | G40: -0.52422622 | H40: 0.28182884 | I40: 1.6543337 | J40: -0.13820805 | K40: 2.6322802
A41: Тульская область | B41: 5 | C41: -0.0012972782 | D41: -0.47302018 | E41: -0.48428553 | F41: 0.27162559 | G41: 1.3493794 | H41: 0.4157673 | I41: 0.5847785 | J41: -0.32200495 | K41: 1.2399314
A42: Ярославская область | B42: 5 | C42: -0.69259686 | D42: 0.13340543 | E42: 0.24550913 | F42: -0.059709415 | G42: 0.77915158 | H42: 0.47994615 | I42: 0.86624041 | J42: -0.6283331 | K42: 0.51060587
...

Sheet взвешенный_метод_ср_связи
A1: Субъект | B1: кластер | C1: X1 | D1: X2 | E1: X3 | F1: X4 | G1: X5 | H1: X6 | I1: X7 | J1: X8 | K1: X9
A2: Республика Калмыкия | B2: 1 | C2: 0.66879679 | D2: -0.2945777 | E2: -0.90053512 | F2: -0.6166342 | G2: -0.40203455 | H2: 3.4377538 | I2: 1.4291642 | J2: -0.26073932 | K2: -0.072854551
A6: Q1(S) | B6: 0
A7: Республика Северная Осетия – Алания | B7: 2 | C7: -0.71804347 | D7: -0.29736586 | E7: -0.91682959 | F7: 0.93664548 | G7: 4.32271 | H7: 0.97105383 | I7: 1.2602871 | J7: 3.1854524 | K7: -1.2530359
A11: Q2(S) | B11: 0
A12: Томская область | B12: 3 | C12: -1.2524223 | D12: -0.64867449 | E12: -0.14506433 | F12: -0.67773144 | G12: -0.15765121 | H12: -1.5933096 | I12: -0.14702245 | J12: 0.014956022 | K12: -3.9183892
A16: Q3(S) | B16: 0
A17: г. Москва | B17: 4 | C17: 2.0853248 | D17: 3.1014057 | E17: -0.81560638 | F17: 5.2745491 | G17: -1.0537234 | H17: -0.91803652 | I17: 0.3033166 | J17: -0.44453621 | K17: -0.56349173
A18: г. Санкт-Петербург | B18: 4 | C18: -0.42964855 | D18: 1.1873313 | E18: 0.86766154 | F18: 5.2651495 | G18: 0.33111546 | H18: -0.82037306 | I18: 0.19073183 | J18: -0.79681358 | K18: 0.92168027
A19: срзнач | C19: =AVERAGE(C17:C18) -> 0.82783811 | D19: =AVERAGE(D17:D18) -> 2.1443685 | E19: =AVERAGE(E17:E18) -> 0.026027581 | F19: =AVERAGE(F17:F18) -> 5.2698493 | G19: =AVERAGE(G17:G18) -> -0.36130399 | H19: =AVERAGE(H17:H18) -> -0.86920479 | I19: =AVERAGE(I17:I18) -> 0.24702421 | J19: =AVERAGE(J17:J18) -> -0.6206749 | K19: =AVERAGE(K17:K18) -> 0.17909427
C20: 2.067128 | D20: 2.067128
C21: =C20*C20 -> 4.2730182 | D21: =D20*D20 -> 4.2730182
A22: Q4(S) | B22: =SUM(C21:D21) -> 8.5460363
A23: Белгородская область | B23: 5 | C23: 0.61790357 | D23: 0.009332148 | E23: -0.32232839 | F23: 0.90139708 | G23: -0.27984288 | H23: -0.62225576 | I23: 0.97882517 | J23: -0.84276281 | K23: 0.25865706
A24: Брянская область | B24: 5 | C24: 0.26165103 | D24: 0.15571074 | E24: -0.081861548 | F24: 0.041336011 | G24: 0.94207381 | H24: -1.5793577 | I24: 0.13443945 | J24: -0.49048543 | K24: -0.32480337
A25: Владимирская область | B25: 5 | C25: -0.16670025 | D25: 1.2263656 | E25: 0.89827539 | F25: 0.20112878 | G25: -1.0129929 | H25: 1.1831231 | I25: 0.07814707 | J25: 0.7807764 | K25: -0.98782658
A26: Воронежская область | B26: 5 | C26: 0.12169467 | D26: -0.47302018 | E26: -1.2214868 | F26: 0.29512452 | G26: 0.33111546 | H26: 0.34600769 | I26: 0.69736326 | J26: 0.30596777 | K26: 0.29843845
A27: Ивановская область | B27: 5 | C27: -0.72652567 | D27: -0.27784872 | E27: -0.16530897 | F27: 0.06013516 | G27: 0.86061269 | H27: 0.47436538 | I27: 0.3033166 | J27: -0.55175106 | K27: -1.0408684
A28: Калужская область | B28: 5 | C28: 1.0462548 | D28: -0.61939877 | E28: 1.1510865 | F28: 0.12358229 | G28: 0.45330713 | H28: 0.11440577 | I28: 0.07814707 | J28: -0.52111825 | K28: -0.28502198
A29: Костромская область | B29: 5 | C29: -1.0573316 | D29: 0.086006651 | E29: -0.30603393 | F29: -0.40984356 | G29: 0.24965435 | H29: 2.0314 | I29: -0.090730073 | J29: -0.2301065 | K29: -1.5978079
A30: Курская область | B30: 5 | C30: -0.077637109 | D30: -0.27227239 | E30: -1.2891335 | F30: 0.14943112 | G30: -0.076190099 | H30: 0.326475 | I30: 0.92253279 | J30: 0.21406932 | K30: -0.92152426
A31: Липецкая область | B31: 5 | C31: -0.13701253 | D31: 0.81092922 | E31: -0.97114448 | F31: 0.60531048 | G31: 0.73842103 | H31: 0.0027903846 | I31: 1.1477023 | J31: -0.75086436 | K31: 0.17909427
A32: Московская область | B32: 5 | C32: 1.5467049 | D32: -0.85639269 | E32: -0.74845342 | F32: 1.2867796 | G32: 0.5754988 | H32: -1.5486634 | I32: 0.3033166 | J32: -1.5320012 | K32: 1.3857965
A33: Орловская область | B33: 5 | C33: -0.38299643 | D33: 0.020484803 | E33: 1.3920472 | F33: 0.2293275 | G33: 0.16819324 | H33: -0.13951923 | I33: 0.64107088 | J33: -0.61301669 | K33: 1.2929733
A34: Рязанская область | B34: 5 | C34: 0.677279 | D34: -0.40749833 | E34: -0.12975741 | F34: -0.064409202 | G34: 0.0052710132 | H34: 0.91524614 | I34: 0.24702421 | J34: -0.21479009 | K34: 0.019968699
... A89: Еврейская автономная область | B89: 5 | C89: -0.7859011 | D89: 0.091582978 | E89: -0.72969009 | F89: -0.57198622 | G89: -0.48349566 | H89: 1.2891577 | I89: -1.7232091 | J89: 1.8376085 | K89: -1.199994
A90: срзнач | C90: =AVERAGE(C23:C89) -> 0.11232627 | D90: =AVERAGE(D23:D89) -> -0.24120725 | E90: =AVERAGE(E23:E89) -> -0.14685518 | F90: =AVERAGE(F23:F89) -> -0.03596146 | G90: =AVERAGE(G23:G89) -> -0.16008289 | H90: =AVERAGE(H23:H89) -> -0.033151435 | I90: =AVERAGE(I23:I89) -> 0.19325239 | J90: =AVERAGE(J23:J89) -> 0.14937464 | K90: =AVERAGE(K23:K89) -> 0.13297952
C91: 1.790657 | D91: 2.101901 | E91: 2.693518 | F91: 1.417512 | G91: 1.973726 | H91: 1.939308 | I91: 3.048086 | J91: 1.777809 | K91: 2.189058 | L91: 3.43424 | M91: 2.235816 | N91: 1.192898 | O91: 1.893573 | P91: 3.041804 | Q91: 1.440742 | R91: 2.087092 | S91: 1.813429 | T91: 2.488857 | U91: 1.808941 | V91: 2.959208 | W91: 3.111918 | X91: 2.662351 | Y91: 1.906831 | Z91: 1.638505 | AA91: 1.995107 | AB91: 1.86037 | AC91: 3.852535 | AD91: 3.599664 | AE91: 5.335259 | AF91: 3.300944 | AG91: 2.850747 | AH91: 4.334883 | AI91: 2.754924 | AJ91: 2.006642 | AK91: 1.852988 | AL91: 2.583849 | AM91: 3.575268 | AN91: 2.001844 | AO91: 1.786661 | AP91: 1.216972 | AQ91: 2.03778 | AR91: 2.060706 | AS91: 1.73393 | AT91: 1.231511 | AU91: 0.8896917 | AV91: 1.182587 | AW91: 1.64627 | AX91: 2.55163 | AY91: 1.751008 | AZ91: 1.834195 | BA91: 1.450213 | BB91: 2.668532 | BC91: 2.452534 | BD91: 2.309812 | BE91: 2.085594 | BF91: 1.079233 | BG91: 1.567126 | BH91: 1.208441 | BI91: 0.9901667 | BJ91: 2.64067 | BK91: 2.681666 | BL91: 2.626583 | BM91: 1.929932 | BN91: 1.961527 | BO91: 1.935989 | BP91: 2.37135 | BQ91: 3.420154 | BR91: 1e-35
C92: =C91*C91 -> 3.2064525 | D92: =D91*D91 -> 4.4179878 | E92: =E91*E91 -> 7.2550392 | F92: =F91*F91 -> 2.0093403 | G92: =G91*G91 -> 3.8955943 | H92: =H91*H91 -> 3.7609155 | I92: =I91*I91 -> 9.2908283 | J92: =J91*J91 -> 3.1606048 | ... BR92: =BR91*BR91 -> 1e-70
A93: Q5(S) | B93: =SUM(C92:BR92) -> 380.04229
A94: Республика Карелия | B94: 6 | C94: -0.21759347 | D94: 0.67012695 | E94: 3.1982642 | F94: -0.62368388 | G94: -0.76860956 | H94: 1.1217346 | I94: -0.090730073 | J94: -0.53643465 | K94: -0.37784523
A95: Республика Коми | B95: 6 | C95: -1.28211 | D95: 2.2496217 | E95: 1.7312683 | F95: -0.69888048 | G95: 0.046001569 | H95: 0.52180191 | I95: -1.4417472 | J95: 0.48976466 | K95: -2.9503753
A96: Ненецкий автономный округ | B96: 6 | C96: 2.2337633 | D96: -0.39076935 | E96: 2.523772 | F96: -0.73436387 | G96: -0.15765121 | H96: -1.6798115 | I96: -2.0609634 | J96: -2.1599739 | K96: -0.52371033
A97: Архангельская область без автономного округа | B97: 6 | C97: -0.70532017 | D97: 1.9666231 | E97: 1.2404592 | F97: -0.66833186 | G97: -0.15765121 | H97: -0.65015961 | I97: -1.1602853 | J97: -1.3635207 | K97: -0.55023126
A98: Мурманская область | B98: 6 | C98: -1.154877 | D98: 0.44149753 | E98: 0.3980846 | F98: -0.68243122 | G98: 0.29038491 | H98: -0.09766346 | I98: 0.52848612 | J98: -3.1555404 | K98: -0.5369708
A99: Новгородская область | B99: 6 | C99: -0.24728118 | D99: 3.9434312 | E99: -0.4324395 | F99: -0.26650005 | G99: -0.27984288 | H99: 0.61388461 | I99: -0.48477674 | J99: 0.15280369 | K99: 0.15257334
A100: Псковская область | B100: 6 | C100: -0.87496423 | D100: 0.33136506 | E100: -0.54551323 | F100: 0.0037377131 | G100: 2.204721 | H100: 0.93198845 | I100: -1.6669167 | J100: -0.79681358 | K100: -1.0673894
A101: Ямало-Ненецкий автономный округ | B101: 6 | C101: -0.014020583 | D101: -0.33500607 | E101: 3.0318631 | F101: -0.73013406 | G101: -0.727879 | H101: -1.1524288 | I101: -1.3854548 | J101: -0.38327058 | K101: 1.0410244
A102: Тюменская область без автономных округов | B102: 6 | C102: 0.60942137 | D102: -0.18444523 | E102: -0.44182116 | F102: -0.52028856 | G102: 2.6934877 | H102: 2.0844173 | I102: -1.7232091 | J102: -0.32200495 | K102: -0.29828244
A103: Камчатский край | B103: 6 | C103: -1.4517541 | D103: 0.71473757 | E103: 0.041581391 | F103: -0.72848914 | G103: 2.6527572 | H103: 1.1384769 | I103: 0.41590136 | J103: -0.90402844 | K103: -0.9082638
...

Sheet метод_Уорда
A1: Субъект | B1: кластер | C1: X1 | D1: X2 | E1: X3 | F1: X4 | G1: X5 | H1: X6 | I1: X7 | J1: X8 | K1: X9
A2: Псковская область | B2: 1 | C2: -0.87496423 | D2: 0.33136506 | E2: -0.54551323 | F2: 0.0037377131 | G2: 2.204721 | H2: 0.93198845 | I2: -1.6669167 | J2: -0.79681358 | K2: -1.0673894
A3: Республика Северная Осетия – Алания | B3: 1 | C3: -0.71804347 | D3: -0.29736586 | E3: -0.91682959 | F3: 0.93664548 | G3: 4.32271 | H3: 0.97105383 | I3: 1.2602871 | J3: 3.1854524 | K3: -1.2530359
A4: Тюменская область без автономных округов | B4: 1 | C4: 0.60942137 | D4: -0.18444523 | E4: -0.44182116 | F4: -0.52028856 | G4: 2.6934877 | H4: 2.0844173 | I4: -1.7232091 | J4: -0.32200495 | K4: -0.29828244
A5: Камчатский край | B5: 1 | C5: -1.4517541 | D5: 0.71473757 | E5: 0.041581391 | F5: -0.72848914 | G5: 2.6527572 | H5: 1.1384769 | I5: 0.41590136 | J5: -0.90402844 | K5: -0.9082638
A6: Сахалинская область | B6: 1 | C6: -1.7740778 | D6: -0.10916481 | E6: 0.021830521 | F6: -0.66128218 | G6: 2.2861822 | H6: -0.42971922 | I6: -0.5973615 | J6: -1.149091 | K6: -0.5369708
A7: срзнач | C7: =AVERAGE(C2:C6) -> -0.84188364 | D7: =AVERAGE(D2:D6) -> 0.091025345 | E7: =AVERAGE(E2:E6) -> -0.36815041 | F7: =AVERAGE(F2:F6) -> -0.19393534 | G7: =AVERAGE(G2:G6) -> 2.8319716 | H7: =AVERAGE(H2:H6) -> 0.93924344 | I7: =AVERAGE(I2:I6) -> -0.46225979 | J7: =AVERAGE(J2:J6) -> 0.0027028948 | K7: =AVERAGE(K2:K6) -> -0.81278846
C8: 1.6365 | D8: 4.154472 | E8: 2.363229 | F8: 1.69966 | G8: 2.207366
C9: =C8*C8 -> 2.6781323 | D9: =D8*D8 -> 17.259638 | E9: =E8*E8 -> 5.5848513 | F9: =F8*F8 -> 2.8888441 | G9: =G8*G8 -> 4.8724647
A10: Q1(S) | B10: =SUM(C9:G9) -> 33.28393
A11: Владимирская область | B11: 2 | C11: -0.16670025 | D11: 1.2263656 | E11: 0.89827539 | F11: 0.20112878 | G11: -1.0129929 | H11: 1.1831231 | I11: 0.07814707 | J11: 0.7807764 | K11: -0.98782658
A12: Республика Карелия | B12: 2 | C12: -0.21759347 | D12: 0.67012695 | E12: 3.1982642 | F12: -0.62368388 | G12: -0.76860956 | H12: 1.1217346 | I12: -0.090730073 | J12: -0.53643465 | K12: -0.37784523
A13: Республика Коми | B13: 2 | C13: -1.28211 | D13: 2.2496217 | E13: 1.7312683 | F13: -0.69888048 | G13: 0.046001569 | H13: 0.52180191 | I13: -1.4417472 | J13: 0.48976466 | K13: -2.9503753
A14: Ненецкий автономный округ | B14: 2 | C14: 2.2337633 | D14: -0.39076935 | E14: 2.523772 | F14: -0.73436387 | G14: -0.15765121 | H14: -1.6798115 | I14: -2.0609634 | J14: -2.1599739 | K14: -0.52371033
A15: Архангельская область без автономного округа | B15: 2 | C15: -0.70532017 | D15: 1.9666231 | E15: 1.2404592 | F15: -0.66833186 | G15: -0.15765121 | H15: -0.65015961 | I15: -1.1602853 | J15: -1.3635207 | K15: -0.55023126
A16: Вологодская область | B16: 2 | C16: 0.20651671 | D16: 0.51538387 | E16: 1.2162644 | F16: -0.47564059 | G16: -0.85007067 | H16: 0.47436538 | I16: -0.76623865 | J16: -1.1337746 | K16: -0.37784523
A17: Мурманская область | B17: 2 | C17: -1.154877 | D17: 0.44149753 | E17: 0.3980846 | F17: -0.68243122 | G17: 0.29038491 | H17: -0.09766346 | I17: 0.52848612 | J17: -3.1555404 | K17: -0.5369708
A18: Новгородская область | B18: 2 | C18: -0.24728118 | D18: 3.9434312 | E18: -0.4324395 | F18: -0.26650005 | G18: -0.27984288 | H18: 0.61388461 | I18: -0.48477674 | J18: 0.15280369 | K18: 0.15257334
A19: Ямало-Ненецкий автономный округ | B19: 2 | C19: -0.014020583 | D19: -0.33500607 | E19: 3.0318631 | F19: -0.73013406 | G19: -0.727879 | H19: -1.1524288 | I19: -1.3854548 | J19: -0.38327058 | K19: 1.0410244
A20: Республика Алтай | B20: 2 | C20: 0.26165103 | D20: 0.33554731 | E20: 0.46326247 | F20: -0.62133399 | G20: -0.727879 | H20: 1.8611865 | I20: -0.25960722 | J20: 0.030272429 | K20: -1.2530359
A21: Республика Хакасия | B21: 2 | C21: 1.4618828 | D21: 0.68406777 | E21: 0.24402781 | F21: -0.51558878 | G21: -1.4202984 | H21: -0.15905192 | I21: -0.14702245 | J21: -0.35263776 | K21: -0.41762662
A22: Томская область | B22: 2 | C22: -1.2524223 | D22: -0.64867449 | E22: -0.14506433 | F22: -0.67773144 | G22: -0.15765121 | H22: -1.5933096 | I22: -0.14702245 | J22: 0.014956022 | K22: -3.9183892
... A26: Чукотский автономный округ | B26: 2 | C26: -2.240599 | D26: 2.3806654 | E26: 1.4404368 | F26: -0.73577381 | G26: -0.44276511 | H26: -1.9923346 | I26: -3.186811 | J26: -0.84276281 | K26: 0.0067082348
A27: срзнач | C27: =AVERAGE(C11:C26) -> -0.31328332 | D27: =AVERAGE(D11:D26) -> 0.90764365 | E27: =AVERAGE(E11:E26) -> 0.99807901 | F27: =AVERAGE(F11:F26) -> -0.57853655 | G27: =AVERAGE(G11:G26) -> -0.50386094 | H27: =AVERAGE(H11:H26) -> -0.016916706 | I27: =AVERAGE(I11:I26) -> -1.0301092 | J27: =AVERAGE(J11:J26) -> -0.49622908 | K27: =AVERAGE(K11:K26) -> -0.57592341
C28: 2.338559 | D28: 2.68297 | E28: 3.265547 | F28: 4.152573 | G28: 1.622529 | H28: 1.165675 | I28: 3.381772 | J28: 3.614076 | K28: 3.14422 | L28: 2.419198 | M28: 2.336522 | N28: 4.408949 | O28: 1.640324 | P28: 4.19256 | Q28: 3.449267 | R28: 3.888658 | S28: 1e-35
C29: =C28*C28 -> 5.4688582 | D29: =D28*D28 -> 7.198328 | E29: =E28*E28 -> 10.663797 | F29: =F28*F28 -> 17.243863 | G29: =G28*G28 -> 2.6326004 | H29: =H28*H28 -> 1.3587982 | I29: =I28*I28 -> 11.436382 | J29: =J28*J28 -> 13.061545 | ... S29: =S28*S28 -> 1e-70
A30: Q2(S) | B30: =SUM(C29:S29) -> 156.9883
A31: Брянская область | B31: 3 | C31: 0.26165103 | D31: 0.15571074 | E31: -0.081861548 | F31: 0.041336011 | G31: 0.94207381 | H31: -1.5793577 | I31: 0.13443945 | J31: -0.49048543 | K31: -0.32480337
A32: Воронежская область | B32: 3 | C32: 0.12169467 | D32: -0.47302018 | E32: -1.2214868 | F32: 0.29512452 | G32: 0.33111546 | H32: 0.34600769 | I32: 0.69736326 | J32: 0.30596777 | K32: 0.29843845
A33: Ивановская область | B33: 3 | C33: -0.72652567 | D33: -0.27784872 | E33: -0.16530897 | F33: 0.06013516 | G33: 0.86061269 | H33: 0.47436538 | I33: 0.3033166 | J33: -0.55175106 | K33: -1.0408684
A34: Калужская область | B34: 3 | C34: 1.0462548 | D34: -0.61939877 | E34: 1.1510865 | F34: 0.12358229 | G34: 0.45330713 | H34: 0.11440577 | I34: 0.07814707 | J34: -0.52111825 | K34: -0.28502198
A35: Костромская область | B35: 3 | C35: -1.0573316 | D35: 0.086006651 | E35: -0.30603393 | F35: -0.40984356 | G35: 0.24965435 | H35: 2.0314 | I35: -0.090730073 | J35: -0.2301065 | K35: -1.5978079
A36: Курская область | B36: 3 | C36: -0.077637109 | D36: -0.27227239 | E36: -1.2891335 | F36: 0.14943112 | G36: -0.076190099 | H36: 0.326475 | I36: 0.92253279 | J36: 0.21406932 | K36: -0.92152426
A37: Липецкая область | B37: 3 | C37: -0.13701253 | D37: 0.81092922 | E37: -0.97114448 | F37: 0.60531048 | G37: 0.73842103 | H37: 0.0027903846 | I37: 1.1477023 | J37: -0.75086436 | K37: 0.17909427
A38: Орловская область | B38: 3 | C38: -0.38299643 | D38: 0.020484803 | E38: 1.3920472 | F38: 0.2293275 | G38: 0.16819324 | H38: -0.13951923 | I38: 0.64107088 | J38: -0.61301669 | K38: 1.2929733
A39: Рязанская область | B39: 3 | C39: 0.677279 | D39: -0.40749833 | E39: -0.12975741 | F39: -0.064409202 | G39: 0.0052710132 | H39: 0.91524614 | I39: 0.24702421 | J39: -0.21479009 | K39: 0.019968699
A40: Смоленская область | B40: 3 | C40: -0.76469559 | D40: 0.4359212 | E40: -0.91929845 | F40: 0.055435373 | G40: 0.5754988 | H40: -0.078130768 | I40: 0.24702421 | J40: 0.045588837 | K40: 1.2266709
A41: Тверская область | B41: 3 | C41: -0.77741889 | D41: -0.66122123 | E41: -0.16185257 | F41: -0.1396058 | G41: -0.56495677 | H41: 0.53296345 | I41: 0.86624041 | J41: -0.24542291 | K41: 0.19235473
A42: Тульская область | B42: 3 | C42: -0.0012972782 | D42: -0.47302018 | E42: -0.48428553 | F42: 0.27162559 | G42: 1.3493794 | H42: 0.4157673 | I42: 0.5847785 | J42: -0.32200495 | K42: 1.2399314
... A79: Амурская область | B79: 3 | C79: -0.66715025 | D79: 0.1821983 | E79: 0.20847625 | F79: -0.65188261 | G79: -0.36130399 | H79: 1.4258865 | I79: -1.1602853 | J79: -0.2301065 | K79: 0.56364773
...

Sheet k-средних
A1: субъект | B1: кластер | C1: расстояние до центра кластера | D1: квадрат расстония | E1: Q4(S) | F1: =E23+E49+E80+E86 -> 59.222782
A2: Брянская область | B2: 1 | C2: 0.7395831 | D2: =C2*C2 -> 0.54698316
A3: Калужская область | B3: 1 | C3: 0.4946936 | D3: =C3*C3 -> 0.24472176
A4: Орловская область | B4: 1 | C4: 0.6964206 | D4: =C4*C4 -> 0.48500165
A5: Республика Карелия | B5: 1 | C5: 1.012832 | D5: =C5*C5 -> 1.0258287
A6: Ненецкий автономный округ | B6: 1 | C6: 1.291676 | D6: =C6*C6 -> 1.6684269
A7: Вологодская область | B7: 1 | C7: 0.5531639 | D7: =C7*C7 -> 0.3059903
A8: Ленинградская область | B8: 1 | C8: 0.9773346 | D8: =C8*C8 -> 0.95518292
A9: Республика Адыгея | B9: 1 | C9: 1.089986 | D9: =C9*C9 -> 1.1880695
A10: Карачаево-Черкесская Республика | B10: 1 | C10: 0.7851588 | D10: =C10*C10 -> 0.61647434
A11: Республика Башкортостан | B11: 1 | C11: 0.4083438 | D11: =C11*C11 -> 0.16674466
A12: Удмуртская Республика | B12: 1 | C12: 0.6870675 | D12: =C12*C12 -> 0.47206175
A13: Пермский край | B13: 1 | C13: 0.4820735 | D13: =C13*C13 -> 0.23239486
... A22: Красноярский край | B22: 1 | C22: 0.4751936 | D22: =C22*C22 -> 0.22580896
A23: Республика Саха (Якутия) | B23: 1 | C23: 0.5479931 | D23: =C23*C23 -> 0.30029644 | E23: =SUM(D2:D23) -> 11.37169
A24: Владимирская область | B24: 2 | C24: 0.8063586 | D24: =C24*C24 -> 0.65021419
A25: Ивановская область | B25: 2 | C25: 0.5847674 | D25: =C25*C25 -> 0.34195291
A26: Костромская область | B26: 2 | C26: 0.7008312 | D26: =C26*C26 -> 0.49116437
A27: Республика Коми | B27: 2 | C27: 1.195927 | D27: =C27*C27 -> 1.4302414
A28: Архангельская область без автономного округа | B28: 2 | C28: 0.8189291 | D28: =C28*C28 -> 0.67064487
A29: Мурманская область | B29: 2 | C29: 1.076084 | D29: =C29*C29 -> 1.1579568
A30: Новгородская область | B30: 2 | C30: 1.192728 | D30: =C30*C30 -> 1.4226001
A31: Псковская область | B31: 2 | C31: 0.846432 | D31: =C31*C31 -> 0.71644713
A32: Кировская область | B32: 2 | C32: 0.5708716 | D32: =C32*C32 -> 0.32589438
A33: Нижегородская область | B33: 2 | C33: 0.5196195 | D33: =C33*C33 -> 0.27000442
A34: Тюменская область без автономных округов | B34: 2 | C34: 1.184296 | D34: =C34*C34 -> 1.402557
A35: Республика Алтай | B35: 2 | C35: 0.7385516 | D35: =C35*C35 -> 0.54545847
... A48: Еврейская автономная область | B48: 2 | C48: 0.9487059 | D48: =C48*C48 -> 0.90004288
A49: Чукотский автономный округ | B49: 2 | C49: 1.503683 | D49: =C49*C49 -> 2.2610626 | E49: =SUM(D24:D49) -> 20.817423
A50: Белгородская область | B50: 3 | C50: 0.6367056 | D50: =C50*C50 -> 0.40539402
A51: Воронежская область | B51: 3 | C51: 0.2645268 | D51: =C51*C51 -> 0.069974428
A52: Курская область | B52: 3 | C52: 0.5176448 | D52: =C52*C52 -> 0.26795614
A53: Липецкая область | B53: 3 | C53: 0.6434089 | D53: =C53*C53 -> 0.41397501
A54: Рязанская область | B54: 3 | C54: 0.4826057 | D54: =C54*C54 -> 0.23290826
A55: Смоленская область | B55: 3 | C55: 0.5424035 | D55: =C55*C55 -> 0.29420156
A56: Тамбовская область | B56: 3 | C56: 0.8943594 | D56: =C56*C56 -> 0.79987874
A57: Тверская область | B57: 3 | C57: 0.491306 | D57: =C57*C57 -> 0.24138159
A58: Тульская область | B58: 3 | C58: 0.5652188 | D58: =C58*C58 -> 0.31947229
A59: Ярославская область | B59: 3 | C59: 0.5804687 | D59: =C59*C59 -> 0.33694391
A60: Калининградская область | B60: 3 | C60: 0.5036217 | D60: =C60*C60 -> 0.25363482
...

Sheet расчет дисперсий
A1: Variable | B1: Between | C1: df | D1: Межгрупповая дисперсия | E1: Within | F1: df | G1: Внутригруппая дисперсия | H1: F | I1: signif.
A2: X1 | B2: 41.35366 | C2: 3 | D2: =B2/C2 -> 13.784553 | E2: 42.64634 | F2: 81 | G2: =E2/F2 -> 0.52649802 | H2: 26.18159 | I2: 6.144512e-12
A3: X2 | B3: 13.686 | C3: 3 | D3: =B3/C3 -> 4.562 | E3: 70.314 | F3: 81 | G3: =E3/F3 -> 0.86807407 | H3: 5.255314 | I3: 0.002305769
A4: X3 | B4: 33.37709 | C4: 3 | D4: =B4/C4 -> 11.125697 | E4: 50.62291 | F4: 81 | G4: =E4/F4 -> 0.6249742 | H4: 17.80185 | I4: 5.757488e-09
A5: X4 | B5: 53.02794 | C5: 3 | D5: =B5/C5 -> 17.67598 | E5: 30.97206 | F5: 81 | G5: =E5/F5 -> 0.38237111 | H5: 46.22728 | I5: 1.637908e-17
A6: X5 | B6: 7.71122 | C6: 3 | D6: =B6/C6 -> 2.5704067 | E6: 76.28878 | F6: 81 | G6: =E6/F6 -> 0.94183679 | H6: 2.729142 | I6: 0.04928016
A7: X6 | B7: 22.91158 | C7: 3 | D7: =B7/C7 -> 7.6371933 | E7: 61.08842 | F7: 81 | G7: =E7/F7 -> 0.75417802 | H7: 10.12651 | I7: 9.759456e-06
A8: X7 | B8: 31.55988 | C8: 3 | D8: =B8/C8 -> 10.51996 | E8: 52.44012 | F8: 81 | G8: =E8/F8 -> 0.64740889 | H8: 16.24933 | I8: 2.33947e-08
A9: X8 | B9: 9.47209 | C9: 3 | D9: =B9/C9 -> 3.1573633 | E9: 74.52791 | F9: 81 | G9: =E9/F9 -> 0.92009765 | H9: 3.431552 | I9: 0.02081515
A10: X9 | B10: 9.895505 | C10: 3 | D10: =B10/C10 -> 3.2985017 | E10: 74.10449 | F10: 81 | G10: =E10/F10 -> 0.91487025 | H10: 3.605431 | I10: 0.01682976
A14: Variable | B14: Межгрупповая дисперсия | C14: Внутригруппая дисперсия
A15: X1 | B15: 13.784553 | C15: 0.52649802
A16: X2 | B16: 4.562 | C16: 0.86807407
A17: X3 | B17: 11.125697 | C17: 0.6249742
A18: X4 | B18: 17.67598 | C18: 0.38237111
A19: X5 | B19: 2.5704067 | C19: 0.94183679
A20: X6 | B20: 7.6371933 | C20: 0.75417802
A21: X7 | B21: 10.51996 | C21: 0.64740889
A22: X8 | B22: 3.1573633 | C22: 0.92009765
A23: X9 | B23: 3.2985017 | C23: 0.91487025

Sheet Графики
A20: Обозначение | B20: Кластер 1 | C20: Кластер 2 | D20: Кластер 3 | E20: Кластер 4 | F20: Кластер 5 | G20: Кластер 6 | L20: Обозначение | M20: Кластер 1 | N20: Кластер 2 | O20: Кластер 3 | P20: Кластер 4 | Q20: Кластер 5 | R20: Кластер 6 | V20: Обозначение | W20: Кластер 1 | X20: Кластер 2 | Y20: Кластер 3 | Z20: Кластер 4
A21: X1 | B21: -0.71804347 | C21: 0.82783811 | D21: 1.465518 | E21: -1.0827782 | F21: 0.12761249 | G21: -0.46328488 | L21: X1 | M21: 0.66879679 | N21: -0.71804347 | O21: -1.2524223 | P21: 0.82783811 | Q21: 0.11232627 | R21: -0.60614363 | V21: X1 | W21: -0.84188364 | X21: -0.31328332 | Y21: -0.17751938 | Z21: 1.1946934
A22: X2 | B22: -0.29736586 | C22: 2.1443685 | D22: -1.6749179 | E22: 2.5860601 | F22: -0.16272349 | G22: 0.24041324 | L22: X2 | M22: -0.2945777 | N22: -0.29736586 | O22: -0.64867449 | P22: 2.1443685 | Q22: -0.24120725 | R22: 1.0086744 | V22: X2 | W22: 0.09 | X22: 0.91 | Y22: -0.081254723 | Z22: -0.73306291
A23: X3 | B23: -0.91682959 | C23: 0.026027581 | D23: -1.2830672 | E23: 0.18329389 | F23: -0.14083856 | G23: 0.52939383 | L23: X3 | M23: -0.90053512 | N23: -0.91682959 | O23: -0.14506433 | P23: 0.026027581 | Q23: -0.14685518 | R23: 0.90382083 | V23: X3 | W23: -0.37 | X23: 1 | Y23: -0.05944028 | Z23: -0.74772922
A24: X4 | B24: 0.93664548 | C24: 5.2698493 | D24: 1.0880458 | E24: -0.5761377 | F24: -0.10348301 | G24: -0.44532696 | L24: X4 | M24: -0.6166342 | N24: 0.93664548 | O24: -0.67773144 | P24: 5.2698493 | Q24: -0.03596146 | R24: -0.59788928 | V24: X4 | W24: -0.19 | X24: -0.58 | Y24: -0.19379722 | Z24: 1.3148217
A25: X5 | B25: 4.32271 | C25: -0.36130399 | D25: 0.45912578 | E25: -0.22553547 | F25: -0.20217066 | G25: 0.088136628 | L25: X5 | M25: -0.40203455 | N25: 4.32271 | O25: -0.15765121 | P25: -0.36130399 | Q25: -0.16008289 | R25: 0.5911644 | V25: X5 | W25: 2.83 | X25: -0.5 | Y25: -0.073696392 | Z25: -0.16579732
A26: X6 | B26: 0.97105383 | C26: -0.86920479 | D26: -1.3541338 | E26: -0.21485961 | F26: -0.066514981 | G26: 0.47417294 | L26: X6 | M26: 3.4377538 | N26: 0.97105383 | O26: -1.5933096 | P26: -0.86920479 | Q26: -0.033151435 | R26: 0.088004436 | V26: X6 | W26: 0.94 | X26: -0.02 | Y26: 0.17738873 | Z26: -0.87450652
A27: X7 | B27: 1.2602871 | C27: 0.24702421 | D27: 0.70540503 | E27: -2.2673688 | F27: 0.39233711 | G27: -0.57795034 | L27: X7 | M27: 1.4291642 | N27: 1.2602871 | O27: -0.14702245 | P27: 0.24702421 | Q27: 0.19325239 | R27: -1.2295682 | V27: X7 | W27: -0.46 | X27: -1.03 | Y27: 0.16316005 | Z27: 0.71988022
A28: X8 | B28: 3.1854524 | C28: -0.6206749 | D28: 0.40661844 | E28: -0.47516902 | F28: 0.15422847 | G28: -0.34471548 | L28: X8 | M28: -0.26073932 | N28: 3.1854524 | O28: 0.014956022 | P28: -0.6206749 | Q28: 0.14937464 | R28: -0.90049388 | V28: X8 | W28: 0 | X28: -0.5 | Y28: 0.22719767 | Z28: -0.213769
A29: X9 | B29: -1.2530359 | C29: 0.17909427 | D29: 0.21319261 | E29: 0.89515934 | F29: 0.29412109 | G29: -0.54931675 | L29: X9 | M29: -0.072854551 | N29: -1.2530359 | O29: -3.9183892 | P29: 0.17909427 | Q29: 0.13297952 | R29: -0.30950284 | V29: X9 | W29: -0.81 | X29: -0.58 | Y29: 0.13552417 | Z29: 0.44253549

Sheet Оценка качества классификации
A1: метод | B1: значение метрики качества классификации Q(S)
A2: полных связей | B2: =полных_связей!B112 -> 461.46107
A3: взвешенный метод средней связи | B3: =взвешенный_метод_ср_связи!B113 -> 533.0723
A4: метод Уорда | B4: =метод_Уорда!B104 -> 538.83851
A5: метод k-средних | B5: ='k-средних'!F1 -> 59.222782
